[2023-04-20T13:52:16.811+0000] {taskinstance.py:1083} INFO - Dependencies all met for <TaskInstance: Training_saving_model.training_saving_model_task manual__2023-04-20T13:50:48.612985+00:00 [queued]>
[2023-04-20T13:52:16.824+0000] {taskinstance.py:1083} INFO - Dependencies all met for <TaskInstance: Training_saving_model.training_saving_model_task manual__2023-04-20T13:50:48.612985+00:00 [queued]>
[2023-04-20T13:52:16.825+0000] {taskinstance.py:1279} INFO - 
--------------------------------------------------------------------------------
[2023-04-20T13:52:16.826+0000] {taskinstance.py:1280} INFO - Starting attempt 2 of 2
[2023-04-20T13:52:16.828+0000] {taskinstance.py:1281} INFO - 
--------------------------------------------------------------------------------
[2023-04-20T13:52:16.880+0000] {taskinstance.py:1300} INFO - Executing <Task(PythonOperator): training_saving_model_task> on 2023-04-20 13:50:48.612985+00:00
[2023-04-20T13:52:16.885+0000] {standard_task_runner.py:55} INFO - Started process 47746 to run task
[2023-04-20T13:52:16.886+0000] {clientserver.py:543} INFO - Closing down clientserver connection
[2023-04-20T13:52:16.895+0000] {standard_task_runner.py:82} INFO - Running: ['airflow', 'tasks', 'run', 'Training_saving_model', 'training_saving_model_task', 'manual__2023-04-20T13:50:48.612985+00:00', '--job-id', '4', '--raw', '--subdir', 'DAGS_FOLDER/dags.py', '--cfg-path', '/tmp/tmpbcn_bh0_']
[2023-04-20T13:52:16.898+0000] {standard_task_runner.py:83} INFO - Job 4: Subtask training_saving_model_task
[2023-04-20T13:52:16.925+0000] {clientserver.py:505} INFO - Error while sending or receiving.
Traceback (most recent call last):
  File "/usr/local/lib/python3.9/site-packages/py4j/clientserver.py", line 503, in send_command
    self.socket.sendall(command.encode("utf-8"))
ConnectionResetError: [Errno 104] Connection reset by peer
[2023-04-20T13:52:16.929+0000] {clientserver.py:543} INFO - Closing down clientserver connection
[2023-04-20T13:52:16.932+0000] {java_gateway.py:1052} INFO - Exception while sending command.
Traceback (most recent call last):
  File "/usr/local/lib/python3.9/site-packages/py4j/clientserver.py", line 503, in send_command
    self.socket.sendall(command.encode("utf-8"))
ConnectionResetError: [Errno 104] Connection reset by peer

During handling of the above exception, another exception occurred:

Traceback (most recent call last):
  File "/usr/local/lib/python3.9/site-packages/py4j/java_gateway.py", line 1038, in send_command
    response = connection.send_command(command)
  File "/usr/local/lib/python3.9/site-packages/py4j/clientserver.py", line 506, in send_command
    raise Py4JNetworkError(
py4j.protocol.Py4JNetworkError: Error while sending
[2023-04-20T13:52:16.935+0000] {clientserver.py:543} INFO - Closing down clientserver connection
[2023-04-20T13:52:16.985+0000] {task_command.py:388} INFO - Running <TaskInstance: Training_saving_model.training_saving_model_task manual__2023-04-20T13:50:48.612985+00:00 [running]> on host 57659a2d2b4a
[2023-04-20T13:52:17.049+0000] {taskinstance.py:1507} INFO - Exporting the following env vars:
AIRFLOW_CTX_DAG_EMAIL=admin@admin.be
AIRFLOW_CTX_DAG_OWNER=Romain
AIRFLOW_CTX_DAG_ID=Training_saving_model
AIRFLOW_CTX_TASK_ID=training_saving_model_task
AIRFLOW_CTX_EXECUTION_DATE=2023-04-20T13:50:48.612985+00:00
AIRFLOW_CTX_TRY_NUMBER=2
AIRFLOW_CTX_DAG_RUN_ID=manual__2023-04-20T13:50:48.612985+00:00
[2023-04-20T13:52:17.050+0000] {taskinstance.py:1768} ERROR - Task failed with exception
Traceback (most recent call last):
  File "/usr/local/lib/python3.9/site-packages/airflow/operators/python.py", line 175, in execute
    return_value = self.execute_callable()
  File "/usr/local/lib/python3.9/site-packages/airflow/operators/python.py", line 192, in execute_callable
    return self.python_callable(*self.op_args, **self.op_kwargs)
TypeError: model_train_saving() missing 2 required positional arguments: 'als' and 'data_sdf'
[2023-04-20T13:52:17.065+0000] {taskinstance.py:1318} INFO - Marking task as FAILED. dag_id=Training_saving_model, task_id=training_saving_model_task, execution_date=20230420T135048, start_date=20230420T135216, end_date=20230420T135217
[2023-04-20T13:52:17.111+0000] {standard_task_runner.py:100} ERROR - Failed to execute job 4 for task training_saving_model_task (model_train_saving() missing 2 required positional arguments: 'als' and 'data_sdf'; 47746)
[2023-04-20T13:52:17.143+0000] {local_task_job.py:208} INFO - Task exited with return code 1
[2023-04-20T13:52:17.169+0000] {taskinstance.py:2578} INFO - 0 downstream tasks scheduled from follow-on schedule check
